<?xml version="1.0"?>
<robot
  name="OUR-I">
  <link
    name="our_base_link">
    <inertial>
      <origin
        xyz="0.000843510816532864 3.33577869448374E-11 0.00987919499672938"
        rpy="0 0 0" />
      <mass
        value="1.00385944508189" />
      <inertia
        ixx="0.00230775779899907"
        ixy="1.13836751459967E-10"
        ixz="9.49187005654923E-07"
        iyy="0.00225058374670214"
        iyz="-2.53420316292721E-11"
        izz="0.00447848391555534" />
    </inertial>
    <visual>
      <origin
        xyz="0 0 0"
        rpy="0 0 0" />
      <geometry>
        <mesh
          filename="package://OUR-I/meshes/base_link.STL" />
      </geometry>
      <material
        name="">
        <color
          rgba="0.0980392156862745 0.0980392156862745 0.0980392156862745 1" />
      </material>
    </visual>
    <collision>
      <origin
        xyz="0 0 0"
        rpy="0 0 0" />
      <geometry>
        <mesh
          filename="package://OUR-I/meshes/base_link.STL" />
      </geometry>
    </collision>
  </link>
  <link
    name="link1">
    <inertial>
      <origin
        xyz="0.00025853 -4.0264E-05 9.0303E-05"
        rpy="0 0 0" />
      <mass
        value="1.0631" />
      <inertia
        ixx="0.0038183"
        ixy="-3.5649E-08"
        ixz="-3.6423E-05"
        iyy="0.0036415"
        iyz="-6.5721E-07"
        izz="0.0035726" />
    </inertial>
    <visual>
      <origin
        xyz="0 0 0"
        rpy="0 0 0" />
      <geometry>
        <mesh
          filename="package://OUR-I/meshes/link1.STL" />
      </geometry>
      <material
        name="">
        <color
          rgba="0.89412 0.91373 0.92941 1" />
      </material>
    </visual>
    <collision>
      <origin
        xyz="0 0 0"
        rpy="0 0 0" />
      <geometry>
        <mesh
          filename="package://OUR-I/meshes/link1.STL" />
      </geometry>
    </collision>
  </link>
  <joint
    name="joint1"
    type="revolute">
    <origin
      xyz="0 0 0.10397"
      rpy="1.6634E-16 3.4934E-15 1.2011E-16" />
    <parent
      link="base_link" />
    <child
      link="link1" />
    <axis
      xyz="0 0 1" />
    <limit
      lower="-3.0543"
      upper="3.0543"
      effort="50"
      velocity="50" />
  </joint>
  <link
    name="link2">
    <inertial>
      <origin
        xyz="0.030564 4.0092E-05 0.21353"
        rpy="0 0 0" />
      <mass
        value="3.0132" />
      <inertia
        ixx="0.11455"
        ixy="-3.9685E-19"
        ixz="5.0003E-16"
        iyy="0.11468"
        iyz="8.6272E-09"
        izz="0.0093722" />
    </inertial>
    <visual>
      <origin
        xyz="0 0 0"
        rpy="0 0 0" />
      <geometry>
        <mesh
          filename="package://OUR-I/meshes/link2.STL" />
      </geometry>
      <material
        name="">
        <color
          rgba="0.89412 0.91373 0.92941 1" />
      </material>
    </visual>
    <collision>
      <origin
        xyz="0 0 0"
        rpy="0 0 0" />
      <geometry>
        <mesh
          filename="package://OUR-I/meshes/link2.STL" />
      </geometry>
    </collision>
  </link>
  <joint
    name="joint2"
    type="revolute">
    <origin
      xyz="0.11653 -8.0183E-05 0"
      rpy="-2.9818E-16 -3.6119E-15 -4.3321E-16" />
    <parent
      link="link1" />
    <child
      link="link2" />
    <axis
      xyz="1 0 0" />
    <limit
      lower="-3.0543"
      upper="3.0543"
      effort="50"
      velocity="50" />
  </joint>
  <link
    name="link3">
    <inertial>
      <origin
        xyz="-0.11198 -4.0014E-05 0.1529"
        rpy="0 0 0" />
      <mass
        value="1.8973" />
      <inertia
        ixx="0.038764"
        ixy="-3.3678E-07"
        ixz="-0.00092149"
        iyy="0.039369"
        iyz="-1.8044E-09"
        izz="0.0037998" />
    </inertial>
    <visual>
      <origin
        xyz="0 0 0"
        rpy="0 0 0" />
      <geometry>
        <mesh
          filename="package://OUR-I/meshes/link3.STL" />
      </geometry>
      <material
        name="">
        <color
          rgba="0.79216 0.81961 0.93333 1" />
      </material>
    </visual>
    <collision>
      <origin
        xyz="0 0 0"
        rpy="0 0 0" />
      <geometry>
        <mesh
          filename="package://OUR-I/meshes/link3.STL" />
      </geometry>
    </collision>
  </link>
  <joint
    name="joint3"
    type="revolute">
    <origin
      xyz="0 8.0183E-05 0.42706"
      rpy="6.245E-17 7.3424E-15 3.131E-16" />
    <parent
      link="link2" />
    <child
      link="link3" />
    <axis
      xyz="1 0 0" />
    <limit
      lower="-3.0543"
      upper="3.0543"
      effort="50"
      velocity="50" />
  </joint>
  <link
    name="link4">
    <inertial>
      <origin
        xyz="0.0078368 -1.5069E-07 0.0025071"
        rpy="0 0 0" />
      <mass
        value="0.47472" />
      <inertia
        ixx="0.0010134"
        ixy="4.0161E-09"
        ixz="7.3001E-06"
        iyy="0.0010983"
        iyz="5.4472E-10"
        izz="0.00095166" />
    </inertial>
    <visual>
      <origin
        xyz="0 0 0"
        rpy="0 0 0" />
      <geometry>
        <mesh
          filename="package://OUR-I/meshes/link4.STL" />
      </geometry>
      <material
        name="">
        <color
          rgba="0.79216 0.81961 0.93333 1" />
      </material>
    </visual>
    <collision>
      <origin
        xyz="0 0 0"
        rpy="0 0 0" />
      <geometry>
        <mesh
          filename="package://OUR-I/meshes/link4.STL" />
      </geometry>
    </collision>
  </link>
  <joint
    name="joint4"
    type="revolute">
    <origin
      xyz="0 -4.0092E-05 0.32847"
      rpy="-6.245E-17 -7.5233E-15 -1.1874E-15" />
    <parent
      link="link3" />
    <child
      link="link4" />
    <axis
      xyz="1 0 0" />
    <limit
      lower="-3.0543"
      upper="3.0543"
      effort="50"
      velocity="50" />
  </joint>
  <link
    name="link5">
    <inertial>
      <origin
        xyz="0.0025071 1.5069E-07 0.12434"
        rpy="0 0 0" />
      <mass
        value="0.47472" />
      <inertia
        ixx="0.00095166"
        ixy="-5.4472E-10"
        ixz="7.3001E-06"
        iyy="0.0010983"
        iyz="-4.0161E-09"
        izz="0.0010134" />
    </inertial>
    <visual>
      <origin
        xyz="0 0 0"
        rpy="0 0 0" />
      <geometry>
        <mesh
          filename="package://OUR-I/meshes/link5.STL" />
      </geometry>
      <material
        name="">
        <color
          rgba="0.79216 0.81961 0.93333 1" />
      </material>
    </visual>
    <collision>
      <origin
        xyz="0 0 0"
        rpy="0 0 0" />
      <geometry>
        <mesh
          filename="package://OUR-I/meshes/link5.STL" />
      </geometry>
    </collision>
  </link>
  <joint
    name="joint5"
    type="revolute">
    <origin
      xyz="0 0 0"
      rpy="-1.0203E-32 0 0" />
    <parent
      link="link4" />
    <child
      link="link5" />
    <axis
      xyz="0 0 -1" />
    <limit
      lower="-3.0543"
      upper="3.0543"
      effort="50"
      velocity="50" />
  </joint>
  <link
    name="link6">
    <inertial>
      <origin
        xyz="0.096192 -3.2388E-05 -9.298E-05"
        rpy="0 0 0" />
      <mass
        value="0.24189" />
      <inertia
        ixx="0.00029991"
        ixy="-1.0462E-07"
        ixz="1.1547E-07"
        iyy="0.00019336"
        iyz="-1.4237E-07"
        izz="0.00019382" />
    </inertial>
    <visual>
      <origin
        xyz="0 0 0"
        rpy="0 0 0" />
      <geometry>
        <mesh
          filename="package://OUR-I/meshes/link6.STL" />
      </geometry>
      <material
        name="">
        <color
          rgba="0.098039 0.098039 0.098039 1" />
      </material>
    </visual>
    <collision>
      <origin
        xyz="0 0 0"
        rpy="0 0 0" />
      <geometry>
        <mesh
          filename="package://OUR-I/meshes/link6.STL" />
      </geometry>
    </collision>
  </link>
  <joint
    name="joint6"
    type="revolute">
    <origin
      xyz="0 0 0.1165"
      rpy="2.254E-31 1.8085E-16 1.3028E-15" />
    <parent
      link="link5" />
    <child
      link="link6" />
    <axis
      xyz="1 0 0" />
    <limit
      lower="-3.0543"
      upper="3.0543"
      effort="50"
      velocity="50" />
  </joint>
</robot>
